<?xml version="1.0"?>

<robot name="dr_one">

  <property name="pi" value="3.1415926535897931" />

  <!-- Main quadrotor link -->
    <link name="base_link">
      <inertial>
        <mass value="1.477" />
        <origin xyz="0 0 0" />
        <inertia ixx="0.01152" ixy="0.0" ixz="0.0" iyy="0.01152" iyz="0.0" izz="0.0218" />
      </inertial>

      <visual>
        <origin xyz="0 0 0" rpy="0 0 0" />
        <geometry>
          <mesh filename="package://dr_one_setup/urdf/quadrotor_base.dae"/>
        </geometry>
      </visual>

      <collision>
        <origin xyz="0 0 0" rpy="0 0 0" />
        <geometry>
          <mesh filename="package://dr_one_setup/urdf/quadrotor_base.stl"/>
        </geometry>
      </collision>
    </link>

    <link name="laser">
        <visual>
            <geometry>
                <cylinder length="0.01" radius="0.036125"/>
            </geometry>
            <origin rpy="0 0 0" xyz="0 0 0.05"/>
            <material name="black">
                <color rgba="1 0 0 1"/>
            </material>
        </visual>
    </link>

    <joint name="base_to_laser" type="continuous">
        <parent link="base_link"/>
        <child link="laser"/>
        <origin xyz="0 0 0.05"/>
        <axis xyz="1 0 0"/>
    </joint>

</robot>
